You're accessing the development server over HTTPS, but it only supports HTTP.
You're accessing the development server over HTTPS, but it only supports HTTP.
You're accessing the development server over HTTPS, but it only supports HTTP.
You're accessing the development server over HTTPS, but it only supports HTTP.
You're accessing the development server over HTTPS, but it only supports HTTP.
You're accessing the development server over HTTPS, but it only supports HTTP.
You're accessing the development server over HTTPS, but it only supports HTTP.
You're accessing the development server over HTTPS, but it only supports HTTP.
You're accessing the development server over HTTPS, but it only supports HTTP.
You're accessing the development server over HTTPS, but it only supports HTTP.
You're accessing the development server over HTTPS, but it only supports HTTP.
You're accessing the development server over HTTPS, but it only supports HTTP.
You're accessing the development server over HTTPS, but it only supports HTTP.
You're accessing the development server over HTTPS, but it only supports HTTP.
You're accessing the development server over HTTPS, but it only supports HTTP.
You're accessing the development server over HTTPS, but it only supports HTTP.
You're accessing the development server over HTTPS, but it only supports HTTP.
You're accessing the development server over HTTPS, but it only supports HTTP.
You're accessing the development server over HTTPS, but it only supports HTTP.
You're accessing the development server over HTTPS, but it only supports HTTP.
You're accessing the development server over HTTPS, but it only supports HTTP.
You're accessing the development server over HTTPS, but it only supports HTTP.
You're accessing the development server over HTTPS, but it only supports HTTP.
You're accessing the development server over HTTPS, but it only supports HTTP.
You're accessing the development server over HTTPS, but it only supports HTTP.
You're accessing the development server over HTTPS, but it only supports HTTP.
You're accessing the development server over HTTPS, but it only supports HTTP.
You're accessing the development server over HTTPS, but it only supports HTTP.
You're accessing the development server over HTTPS, but it only supports HTTP.
You're accessing the development server over HTTPS, but it only supports HTTP.
You're accessing the development server over HTTPS, but it only supports HTTP.
You're accessing the development server over HTTPS, but it only supports HTTP.
You're accessing the development server over HTTPS, but it only supports HTTP.
You're accessing the development server over HTTPS, but it only supports HTTP.
You're accessing the development server over HTTPS, but it only supports HTTP.
You're accessing the development server over HTTPS, but it only supports HTTP.
You're accessing the development server over HTTPS, but it only supports HTTP.
You're accessing the development server over HTTPS, but it only supports HTTP.
You're accessing the development server over HTTPS, but it only supports HTTP.
You're accessing the development server over HTTPS, but it only supports HTTP.
You're accessing the development server over HTTPS, but it only supports HTTP.
You're accessing the development server over HTTPS, but it only supports HTTP.
You're accessing the development server over HTTPS, but it only supports HTTP.
You're accessing the development server over HTTPS, but it only supports HTTP.
You're accessing the development server over HTTPS, but it only supports HTTP.
You're accessing the development server over HTTPS, but it only supports HTTP.
You're accessing the development server over HTTPS, but it only supports HTTP.
You're accessing the development server over HTTPS, but it only supports HTTP.
You're accessing the development server over HTTPS, but it only supports HTTP.
You're accessing the development server over HTTPS, but it only supports HTTP.
You're accessing the development server over HTTPS, but it only supports HTTP.
You're accessing the development server over HTTPS, but it only supports HTTP.
You're accessing the development server over HTTPS, but it only supports HTTP.
You're accessing the development server over HTTPS, but it only supports HTTP.
You're accessing the development server over HTTPS, but it only supports HTTP.
You're accessing the development server over HTTPS, but it only supports HTTP.
You're accessing the development server over HTTPS, but it only supports HTTP.
You're accessing the development server over HTTPS, but it only supports HTTP.
You're accessing the development server over HTTPS, but it only supports HTTP.
You're accessing the development server over HTTPS, but it only supports HTTP.
You're accessing the development server over HTTPS, but it only supports HTTP.
You're accessing the development server over HTTPS, but it only supports HTTP.
You're accessing the development server over HTTPS, but it only supports HTTP.
You're accessing the development server over HTTPS, but it only supports HTTP.
You're accessing the development server over HTTPS, but it only supports HTTP.
You're accessing the development server over HTTPS, but it only supports HTTP.
You're accessing the development server over HTTPS, but it only supports HTTP.
You're accessing the development server over HTTPS, but it only supports HTTP.
You're accessing the development server over HTTPS, but it only supports HTTP.
You're accessing the development server over HTTPS, but it only supports HTTP.
Internal Server Error: /register/
Traceback (most recent call last):
  File "C:\Users\Oumaima\AppData\Local\Programs\Python\Python312\Lib\site-packages\django\contrib\auth\__init__.py", line 57, in _get_backend_from_user
    backend = backend or user.backend
                         ^^^^^^^^^^^^
AttributeError: 'User' object has no attribute 'backend'

During handling of the above exception, another exception occurred:

Traceback (most recent call last):
  File "C:\Users\Oumaima\AppData\Local\Programs\Python\Python312\Lib\site-packages\django\core\handlers\exception.py", line 55, in inner
    response = get_response(request)
               ^^^^^^^^^^^^^^^^^^^^^
  File "C:\Users\Oumaima\AppData\Local\Programs\Python\Python312\Lib\site-packages\django\core\handlers\base.py", line 197, in _get_response
    response = wrapped_callback(request, *callback_args, **callback_kwargs)
               ^^^^^^^^^^^^^^^^^^^^^^^^^^^^^^^^^^^^^^^^^^^^^^^^^^^^^^^^^^^^
  File "C:\Users\Oumaima\Desktop\security2_pour_reservation\accounts\views.py", line 15, in register_view
    login(request, user)
  File "C:\Users\Oumaima\AppData\Local\Programs\Python\Python312\Lib\site-packages\django\contrib\auth\__init__.py", line 189, in login
    backend = _get_backend_from_user(user=user, backend=backend)
              ^^^^^^^^^^^^^^^^^^^^^^^^^^^^^^^^^^^^^^^^^^^^^^^^^^
  File "C:\Users\Oumaima\AppData\Local\Programs\Python\Python312\Lib\site-packages\django\contrib\auth\__init__.py", line 63, in _get_backend_from_user
    raise ValueError(
ValueError: You have multiple authentication backends configured and therefore must provide the `backend` argument or set the `backend` attribute on the user.
"POST /register/ HTTP/1.1" 500 87804
Internal Server Error: /login/
Traceback (most recent call last):
  File "C:\Users\Oumaima\AppData\Local\Programs\Python\Python312\Lib\site-packages\django\core\handlers\exception.py", line 55, in inner
    response = get_response(request)
               ^^^^^^^^^^^^^^^^^^^^^
  File "C:\Users\Oumaima\AppData\Local\Programs\Python\Python312\Lib\site-packages\django\core\handlers\base.py", line 197, in _get_response
    response = wrapped_callback(request, *callback_args, **callback_kwargs)
               ^^^^^^^^^^^^^^^^^^^^^^^^^^^^^^^^^^^^^^^^^^^^^^^^^^^^^^^^^^^^
  File "C:\Users\Oumaima\Desktop\security2_pour_reservation\accounts\views.py", line 36, in login_view
    user = authenticate(username=username, password=password)
           ^^^^^^^^^^^^^^^^^^^^^^^^^^^^^^^^^^^^^^^^^^^^^^^^^^
  File "C:\Users\Oumaima\AppData\Local\Programs\Python\Python312\Lib\site-packages\django\views\decorators\debug.py", line 75, in sensitive_variables_wrapper
    return func(*func_args, **func_kwargs)
           ^^^^^^^^^^^^^^^^^^^^^^^^^^^^^^^
  File "C:\Users\Oumaima\AppData\Local\Programs\Python\Python312\Lib\site-packages\django\contrib\auth\__init__.py", line 114, in authenticate
    user = backend.authenticate(request, **credentials)
           ^^^^^^^^^^^^^^^^^^^^^^^^^^^^^^^^^^^^^^^^^^^^
  File "C:\Users\Oumaima\AppData\Local\Programs\Python\Python312\Lib\site-packages\axes\helpers.py", line 617, in inner
    return func(*args, **kwargs)
           ^^^^^^^^^^^^^^^^^^^^^
  File "C:\Users\Oumaima\AppData\Local\Programs\Python\Python312\Lib\site-packages\axes\backends.py", line 46, in authenticate
    raise AxesBackendRequestParameterRequired(
axes.exceptions.AxesBackendRequestParameterRequired: AxesBackend requires a request as an argument to authenticate
"POST /login/ HTTP/1.1" 500 92014
Internal Server Error: /login/
Traceback (most recent call last):
  File "C:\Users\Oumaima\AppData\Local\Programs\Python\Python312\Lib\site-packages\django\core\handlers\exception.py", line 55, in inner
    response = get_response(request)
               ^^^^^^^^^^^^^^^^^^^^^
  File "C:\Users\Oumaima\AppData\Local\Programs\Python\Python312\Lib\site-packages\django\core\handlers\base.py", line 197, in _get_response
    response = wrapped_callback(request, *callback_args, **callback_kwargs)
               ^^^^^^^^^^^^^^^^^^^^^^^^^^^^^^^^^^^^^^^^^^^^^^^^^^^^^^^^^^^^
  File "C:\Users\Oumaima\Desktop\security2_pour_reservation\accounts\views.py", line 36, in login_view
    user = authenticate(username=username, password=password)
           ^^^^^^^^^^^^^^^^^^^^^^^^^^^^^^^^^^^^^^^^^^^^^^^^^^
  File "C:\Users\Oumaima\AppData\Local\Programs\Python\Python312\Lib\site-packages\django\views\decorators\debug.py", line 75, in sensitive_variables_wrapper
    return func(*func_args, **func_kwargs)
           ^^^^^^^^^^^^^^^^^^^^^^^^^^^^^^^
  File "C:\Users\Oumaima\AppData\Local\Programs\Python\Python312\Lib\site-packages\django\contrib\auth\__init__.py", line 114, in authenticate
    user = backend.authenticate(request, **credentials)
           ^^^^^^^^^^^^^^^^^^^^^^^^^^^^^^^^^^^^^^^^^^^^
  File "C:\Users\Oumaima\AppData\Local\Programs\Python\Python312\Lib\site-packages\axes\helpers.py", line 617, in inner
    return func(*args, **kwargs)
           ^^^^^^^^^^^^^^^^^^^^^
  File "C:\Users\Oumaima\AppData\Local\Programs\Python\Python312\Lib\site-packages\axes\backends.py", line 46, in authenticate
    raise AxesBackendRequestParameterRequired(
axes.exceptions.AxesBackendRequestParameterRequired: AxesBackend requires a request as an argument to authenticate
"POST /login/ HTTP/1.1" 500 92014
Internal Server Error: /login/
Traceback (most recent call last):
  File "C:\Users\Oumaima\AppData\Local\Programs\Python\Python312\Lib\site-packages\django\core\handlers\exception.py", line 55, in inner
    response = get_response(request)
               ^^^^^^^^^^^^^^^^^^^^^
  File "C:\Users\Oumaima\AppData\Local\Programs\Python\Python312\Lib\site-packages\django\core\handlers\base.py", line 197, in _get_response
    response = wrapped_callback(request, *callback_args, **callback_kwargs)
               ^^^^^^^^^^^^^^^^^^^^^^^^^^^^^^^^^^^^^^^^^^^^^^^^^^^^^^^^^^^^
  File "C:\Users\Oumaima\Desktop\security2_pour_reservation\accounts\views.py", line 36, in login_view
    user = authenticate(username=username, password=password)
           ^^^^^^^^^^^^^^^^^^^^^^^^^^^^^^^^^^^^^^^^^^^^^^^^^^
  File "C:\Users\Oumaima\AppData\Local\Programs\Python\Python312\Lib\site-packages\django\views\decorators\debug.py", line 75, in sensitive_variables_wrapper
    return func(*func_args, **func_kwargs)
           ^^^^^^^^^^^^^^^^^^^^^^^^^^^^^^^
  File "C:\Users\Oumaima\AppData\Local\Programs\Python\Python312\Lib\site-packages\django\contrib\auth\__init__.py", line 114, in authenticate
    user = backend.authenticate(request, **credentials)
           ^^^^^^^^^^^^^^^^^^^^^^^^^^^^^^^^^^^^^^^^^^^^
  File "C:\Users\Oumaima\AppData\Local\Programs\Python\Python312\Lib\site-packages\axes\helpers.py", line 617, in inner
    return func(*args, **kwargs)
           ^^^^^^^^^^^^^^^^^^^^^
  File "C:\Users\Oumaima\AppData\Local\Programs\Python\Python312\Lib\site-packages\axes\backends.py", line 46, in authenticate
    raise AxesBackendRequestParameterRequired(
axes.exceptions.AxesBackendRequestParameterRequired: AxesBackend requires a request as an argument to authenticate
"POST /login/ HTTP/1.1" 500 92014
Internal Server Error: /login/
Traceback (most recent call last):
  File "C:\Users\Oumaima\AppData\Local\Programs\Python\Python312\Lib\site-packages\django\core\handlers\exception.py", line 55, in inner
    response = get_response(request)
               ^^^^^^^^^^^^^^^^^^^^^
  File "C:\Users\Oumaima\AppData\Local\Programs\Python\Python312\Lib\site-packages\django\core\handlers\base.py", line 197, in _get_response
    response = wrapped_callback(request, *callback_args, **callback_kwargs)
               ^^^^^^^^^^^^^^^^^^^^^^^^^^^^^^^^^^^^^^^^^^^^^^^^^^^^^^^^^^^^
  File "C:\Users\Oumaima\Desktop\security2_pour_reservation\accounts\views.py", line 43, in login_view
    user = authenticate(username=username, password=password)
           ^^^^^^^^^^^^^^^^^^^^^^^^^^^^^^^^^^^^^^^^^^^^^^^^^^
  File "C:\Users\Oumaima\AppData\Local\Programs\Python\Python312\Lib\site-packages\django\views\decorators\debug.py", line 75, in sensitive_variables_wrapper
    return func(*func_args, **func_kwargs)
           ^^^^^^^^^^^^^^^^^^^^^^^^^^^^^^^
  File "C:\Users\Oumaima\AppData\Local\Programs\Python\Python312\Lib\site-packages\django\contrib\auth\__init__.py", line 114, in authenticate
    user = backend.authenticate(request, **credentials)
           ^^^^^^^^^^^^^^^^^^^^^^^^^^^^^^^^^^^^^^^^^^^^
  File "C:\Users\Oumaima\AppData\Local\Programs\Python\Python312\Lib\site-packages\axes\helpers.py", line 617, in inner
    return func(*args, **kwargs)
           ^^^^^^^^^^^^^^^^^^^^^
  File "C:\Users\Oumaima\AppData\Local\Programs\Python\Python312\Lib\site-packages\axes\backends.py", line 46, in authenticate
    raise AxesBackendRequestParameterRequired(
axes.exceptions.AxesBackendRequestParameterRequired: AxesBackend requires a request as an argument to authenticate
"POST /login/ HTTP/1.1" 500 92014
Internal Server Error: /login/
Traceback (most recent call last):
  File "C:\Users\Oumaima\AppData\Local\Programs\Python\Python312\Lib\site-packages\django\core\handlers\exception.py", line 55, in inner
    response = get_response(request)
               ^^^^^^^^^^^^^^^^^^^^^
  File "C:\Users\Oumaima\AppData\Local\Programs\Python\Python312\Lib\site-packages\django\core\handlers\base.py", line 197, in _get_response
    response = wrapped_callback(request, *callback_args, **callback_kwargs)
               ^^^^^^^^^^^^^^^^^^^^^^^^^^^^^^^^^^^^^^^^^^^^^^^^^^^^^^^^^^^^
  File "C:\Users\Oumaima\Desktop\security2_pour_reservation\accounts\views.py", line 43, in login_view
    user = authenticate(username=username, password=password)
           ^^^^^^^^^^^^^^^^^^^^^^^^^^^^^^^^^^^^^^^^^^^^^^^^^^
  File "C:\Users\Oumaima\AppData\Local\Programs\Python\Python312\Lib\site-packages\django\views\decorators\debug.py", line 75, in sensitive_variables_wrapper
    return func(*func_args, **func_kwargs)
           ^^^^^^^^^^^^^^^^^^^^^^^^^^^^^^^
  File "C:\Users\Oumaima\AppData\Local\Programs\Python\Python312\Lib\site-packages\django\contrib\auth\__init__.py", line 114, in authenticate
    user = backend.authenticate(request, **credentials)
           ^^^^^^^^^^^^^^^^^^^^^^^^^^^^^^^^^^^^^^^^^^^^
  File "C:\Users\Oumaima\AppData\Local\Programs\Python\Python312\Lib\site-packages\axes\helpers.py", line 617, in inner
    return func(*args, **kwargs)
           ^^^^^^^^^^^^^^^^^^^^^
  File "C:\Users\Oumaima\AppData\Local\Programs\Python\Python312\Lib\site-packages\axes\backends.py", line 46, in authenticate
    raise AxesBackendRequestParameterRequired(
axes.exceptions.AxesBackendRequestParameterRequired: AxesBackend requires a request as an argument to authenticate
"POST /login/ HTTP/1.1" 500 92014
Internal Server Error: /login/
Traceback (most recent call last):
  File "C:\Users\Oumaima\AppData\Local\Programs\Python\Python312\Lib\site-packages\django\core\handlers\exception.py", line 55, in inner
    response = get_response(request)
               ^^^^^^^^^^^^^^^^^^^^^
  File "C:\Users\Oumaima\AppData\Local\Programs\Python\Python312\Lib\site-packages\django\core\handlers\base.py", line 197, in _get_response
    response = wrapped_callback(request, *callback_args, **callback_kwargs)
               ^^^^^^^^^^^^^^^^^^^^^^^^^^^^^^^^^^^^^^^^^^^^^^^^^^^^^^^^^^^^
  File "C:\Users\Oumaima\Desktop\security2_pour_reservation\accounts\views.py", line 43, in login_view
    user = authenticate(username=username, password=password)
           ^^^^^^^^^^^^^^^^^^^^^^^^^^^^^^^^^^^^^^^^^^^^^^^^^^
  File "C:\Users\Oumaima\AppData\Local\Programs\Python\Python312\Lib\site-packages\django\views\decorators\debug.py", line 75, in sensitive_variables_wrapper
    return func(*func_args, **func_kwargs)
           ^^^^^^^^^^^^^^^^^^^^^^^^^^^^^^^
  File "C:\Users\Oumaima\AppData\Local\Programs\Python\Python312\Lib\site-packages\django\contrib\auth\__init__.py", line 114, in authenticate
    user = backend.authenticate(request, **credentials)
           ^^^^^^^^^^^^^^^^^^^^^^^^^^^^^^^^^^^^^^^^^^^^
  File "C:\Users\Oumaima\AppData\Local\Programs\Python\Python312\Lib\site-packages\axes\helpers.py", line 617, in inner
    return func(*args, **kwargs)
           ^^^^^^^^^^^^^^^^^^^^^
  File "C:\Users\Oumaima\AppData\Local\Programs\Python\Python312\Lib\site-packages\axes\backends.py", line 46, in authenticate
    raise AxesBackendRequestParameterRequired(
axes.exceptions.AxesBackendRequestParameterRequired: AxesBackend requires a request as an argument to authenticate
"POST /login/ HTTP/1.1" 500 92014
Internal Server Error: /register/
Traceback (most recent call last):
  File "C:\Users\Oumaima\AppData\Local\Programs\Python\Python312\Lib\site-packages\django\core\handlers\exception.py", line 55, in inner
    response = get_response(request)
               ^^^^^^^^^^^^^^^^^^^^^
  File "C:\Users\Oumaima\AppData\Local\Programs\Python\Python312\Lib\site-packages\django\core\handlers\base.py", line 197, in _get_response
    response = wrapped_callback(request, *callback_args, **callback_kwargs)
               ^^^^^^^^^^^^^^^^^^^^^^^^^^^^^^^^^^^^^^^^^^^^^^^^^^^^^^^^^^^^
  File "C:\Users\Oumaima\Desktop\security2_pour_reservation\accounts\views.py", line 29, in register_view
    user = authenticate(username=username, password=password)
           ^^^^^^^^^^^^^^^^^^^^^^^^^^^^^^^^^^^^^^^^^^^^^^^^^^
  File "C:\Users\Oumaima\AppData\Local\Programs\Python\Python312\Lib\site-packages\django\views\decorators\debug.py", line 75, in sensitive_variables_wrapper
    return func(*func_args, **func_kwargs)
           ^^^^^^^^^^^^^^^^^^^^^^^^^^^^^^^
  File "C:\Users\Oumaima\AppData\Local\Programs\Python\Python312\Lib\site-packages\django\contrib\auth\__init__.py", line 114, in authenticate
    user = backend.authenticate(request, **credentials)
           ^^^^^^^^^^^^^^^^^^^^^^^^^^^^^^^^^^^^^^^^^^^^
  File "C:\Users\Oumaima\AppData\Local\Programs\Python\Python312\Lib\site-packages\axes\helpers.py", line 617, in inner
    return func(*args, **kwargs)
           ^^^^^^^^^^^^^^^^^^^^^
  File "C:\Users\Oumaima\AppData\Local\Programs\Python\Python312\Lib\site-packages\axes\backends.py", line 46, in authenticate
    raise AxesBackendRequestParameterRequired(
axes.exceptions.AxesBackendRequestParameterRequired: AxesBackend requires a request as an argument to authenticate
"POST /register/ HTTP/1.1" 500 92552
You're accessing the development server over HTTPS, but it only supports HTTP.
You're accessing the development server over HTTPS, but it only supports HTTP.
You're accessing the development server over HTTPS, but it only supports HTTP.
You're accessing the development server over HTTPS, but it only supports HTTP.
You're accessing the development server over HTTPS, but it only supports HTTP.
You're accessing the development server over HTTPS, but it only supports HTTP.
You're accessing the development server over HTTPS, but it only supports HTTP.
You're accessing the development server over HTTPS, but it only supports HTTP.
You're accessing the development server over HTTPS, but it only supports HTTP.
You're accessing the development server over HTTPS, but it only supports HTTP.
You're accessing the development server over HTTPS, but it only supports HTTP.
You're accessing the development server over HTTPS, but it only supports HTTP.
You're accessing the development server over HTTPS, but it only supports HTTP.
You're accessing the development server over HTTPS, but it only supports HTTP.
You're accessing the development server over HTTPS, but it only supports HTTP.
You're accessing the development server over HTTPS, but it only supports HTTP.
You're accessing the development server over HTTPS, but it only supports HTTP.
You're accessing the development server over HTTPS, but it only supports HTTP.
You're accessing the development server over HTTPS, but it only supports HTTP.
You're accessing the development server over HTTPS, but it only supports HTTP.
You're accessing the development server over HTTPS, but it only supports HTTP.
You're accessing the development server over HTTPS, but it only supports HTTP.
You're accessing the development server over HTTPS, but it only supports HTTP.
You're accessing the development server over HTTPS, but it only supports HTTP.
You're accessing the development server over HTTPS, but it only supports HTTP.
You're accessing the development server over HTTPS, but it only supports HTTP.
You're accessing the development server over HTTPS, but it only supports HTTP.
You're accessing the development server over HTTPS, but it only supports HTTP.
You're accessing the development server over HTTPS, but it only supports HTTP.
You're accessing the development server over HTTPS, but it only supports HTTP.
You're accessing the development server over HTTPS, but it only supports HTTP.
You're accessing the development server over HTTPS, but it only supports HTTP.
You're accessing the development server over HTTPS, but it only supports HTTP.
You're accessing the development server over HTTPS, but it only supports HTTP.
You're accessing the development server over HTTPS, but it only supports HTTP.
You're accessing the development server over HTTPS, but it only supports HTTP.
You're accessing the development server over HTTPS, but it only supports HTTP.
You're accessing the development server over HTTPS, but it only supports HTTP.
You're accessing the development server over HTTPS, but it only supports HTTP.
You're accessing the development server over HTTPS, but it only supports HTTP.
You're accessing the development server over HTTPS, but it only supports HTTP.
You're accessing the development server over HTTPS, but it only supports HTTP.
You're accessing the development server over HTTPS, but it only supports HTTP.
You're accessing the development server over HTTPS, but it only supports HTTP.
You're accessing the development server over HTTPS, but it only supports HTTP.
You're accessing the development server over HTTPS, but it only supports HTTP.
Failed to send password reset email to 2
Traceback (most recent call last):
  File "C:\Users\Oumaima\AppData\Local\Programs\Python\Python312\Lib\site-packages\django\contrib\auth\forms.py", line 434, in send_mail
    email_message.send()
  File "C:\Users\Oumaima\AppData\Local\Programs\Python\Python312\Lib\site-packages\django\core\mail\message.py", line 307, in send
    return self.get_connection(fail_silently).send_messages([self])
           ^^^^^^^^^^^^^^^^^^^^^^^^^^^^^^^^^^^^^^^^^^^^^^^^^^^^^^^^
  File "C:\Users\Oumaima\AppData\Local\Programs\Python\Python312\Lib\site-packages\django\core\mail\backends\smtp.py", line 128, in send_messages
    new_conn_created = self.open()
                       ^^^^^^^^^^^
  File "C:\Users\Oumaima\AppData\Local\Programs\Python\Python312\Lib\site-packages\django\core\mail\backends\smtp.py", line 95, in open
    self.connection.login(self.username, self.password)
  File "C:\Users\Oumaima\AppData\Local\Programs\Python\Python312\Lib\smtplib.py", line 750, in login
    raise last_exception
  File "C:\Users\Oumaima\AppData\Local\Programs\Python\Python312\Lib\smtplib.py", line 739, in login
    (code, resp) = self.auth(
                   ^^^^^^^^^^
  File "C:\Users\Oumaima\AppData\Local\Programs\Python\Python312\Lib\smtplib.py", line 662, in auth
    raise SMTPAuthenticationError(code, resp)
smtplib.SMTPAuthenticationError: (535, b'5.7.8 Username and Password not accepted. For more information, go to\n5.7.8  https://support.google.com/mail/?p=BadCredentials 5b1f17b1804b1-45decf817efsm36248365e9.18 - gsmtp')
Failed to send password reset email to 3
Traceback (most recent call last):
  File "C:\Users\Oumaima\AppData\Local\Programs\Python\Python312\Lib\site-packages\django\contrib\auth\forms.py", line 434, in send_mail
    email_message.send()
  File "C:\Users\Oumaima\AppData\Local\Programs\Python\Python312\Lib\site-packages\django\core\mail\message.py", line 307, in send
    return self.get_connection(fail_silently).send_messages([self])
           ^^^^^^^^^^^^^^^^^^^^^^^^^^^^^^^^^^^^^^^^^^^^^^^^^^^^^^^^
  File "C:\Users\Oumaima\AppData\Local\Programs\Python\Python312\Lib\site-packages\django\core\mail\backends\smtp.py", line 128, in send_messages
    new_conn_created = self.open()
                       ^^^^^^^^^^^
  File "C:\Users\Oumaima\AppData\Local\Programs\Python\Python312\Lib\site-packages\django\core\mail\backends\smtp.py", line 95, in open
    self.connection.login(self.username, self.password)
  File "C:\Users\Oumaima\AppData\Local\Programs\Python\Python312\Lib\smtplib.py", line 750, in login
    raise last_exception
  File "C:\Users\Oumaima\AppData\Local\Programs\Python\Python312\Lib\smtplib.py", line 739, in login
    (code, resp) = self.auth(
                   ^^^^^^^^^^
  File "C:\Users\Oumaima\AppData\Local\Programs\Python\Python312\Lib\smtplib.py", line 662, in auth
    raise SMTPAuthenticationError(code, resp)
smtplib.SMTPAuthenticationError: (535, b'5.7.8 Username and Password not accepted. For more information, go to\n5.7.8  https://support.google.com/mail/?p=BadCredentials ffacd0b85a97d-3e75223ea47sm2510224f8f.46 - gsmtp')
Failed to send password reset email to 4
Traceback (most recent call last):
  File "C:\Users\Oumaima\AppData\Local\Programs\Python\Python312\Lib\site-packages\django\contrib\auth\forms.py", line 434, in send_mail
    email_message.send()
  File "C:\Users\Oumaima\AppData\Local\Programs\Python\Python312\Lib\site-packages\django\core\mail\message.py", line 307, in send
    return self.get_connection(fail_silently).send_messages([self])
           ^^^^^^^^^^^^^^^^^^^^^^^^^^^^^^^^^^^^^^^^^^^^^^^^^^^^^^^^
  File "C:\Users\Oumaima\AppData\Local\Programs\Python\Python312\Lib\site-packages\django\core\mail\backends\smtp.py", line 128, in send_messages
    new_conn_created = self.open()
                       ^^^^^^^^^^^
  File "C:\Users\Oumaima\AppData\Local\Programs\Python\Python312\Lib\site-packages\django\core\mail\backends\smtp.py", line 95, in open
    self.connection.login(self.username, self.password)
  File "C:\Users\Oumaima\AppData\Local\Programs\Python\Python312\Lib\smtplib.py", line 750, in login
    raise last_exception
  File "C:\Users\Oumaima\AppData\Local\Programs\Python\Python312\Lib\smtplib.py", line 739, in login
    (code, resp) = self.auth(
                   ^^^^^^^^^^
  File "C:\Users\Oumaima\AppData\Local\Programs\Python\Python312\Lib\smtplib.py", line 662, in auth
    raise SMTPAuthenticationError(code, resp)
smtplib.SMTPAuthenticationError: (535, b'5.7.8 Username and Password not accepted. For more information, go to\n5.7.8  https://support.google.com/mail/?p=BadCredentials ffacd0b85a97d-3e7521bfdc6sm2559771f8f.8 - gsmtp')
Internal Server Error: /register/
Traceback (most recent call last):
  File "C:\Users\Oumaima\AppData\Local\Programs\Python\Python312\Lib\site-packages\django\core\handlers\exception.py", line 55, in inner
    response = get_response(request)
               ^^^^^^^^^^^^^^^^^^^^^
  File "C:\Users\Oumaima\AppData\Local\Programs\Python\Python312\Lib\site-packages\django\core\handlers\base.py", line 197, in _get_response
    response = wrapped_callback(request, *callback_args, **callback_kwargs)
               ^^^^^^^^^^^^^^^^^^^^^^^^^^^^^^^^^^^^^^^^^^^^^^^^^^^^^^^^^^^^
  File "C:\Users\Oumaima\Desktop\security2_pour_reservation\accounts\views.py", line 22, in register_view
    user = authenticate(username=username, password=password)
           ^^^^^^^^^^^^^^^^^^^^^^^^^^^^^^^^^^^^^^^^^^^^^^^^^^
  File "C:\Users\Oumaima\AppData\Local\Programs\Python\Python312\Lib\site-packages\django\views\decorators\debug.py", line 75, in sensitive_variables_wrapper
    return func(*func_args, **func_kwargs)
           ^^^^^^^^^^^^^^^^^^^^^^^^^^^^^^^
  File "C:\Users\Oumaima\AppData\Local\Programs\Python\Python312\Lib\site-packages\django\contrib\auth\__init__.py", line 114, in authenticate
    user = backend.authenticate(request, **credentials)
           ^^^^^^^^^^^^^^^^^^^^^^^^^^^^^^^^^^^^^^^^^^^^
  File "C:\Users\Oumaima\AppData\Local\Programs\Python\Python312\Lib\site-packages\axes\helpers.py", line 617, in inner
    return func(*args, **kwargs)
           ^^^^^^^^^^^^^^^^^^^^^
  File "C:\Users\Oumaima\AppData\Local\Programs\Python\Python312\Lib\site-packages\axes\backends.py", line 46, in authenticate
    raise AxesBackendRequestParameterRequired(
axes.exceptions.AxesBackendRequestParameterRequired: AxesBackend requires a request as an argument to authenticate
"POST /register/ HTTP/1.1" 500 92534
Failed to send password reset email to 5
Traceback (most recent call last):
  File "C:\Users\Oumaima\AppData\Local\Programs\Python\Python312\Lib\site-packages\django\contrib\auth\forms.py", line 434, in send_mail
    email_message.send()
  File "C:\Users\Oumaima\AppData\Local\Programs\Python\Python312\Lib\site-packages\django\core\mail\message.py", line 307, in send
    return self.get_connection(fail_silently).send_messages([self])
           ^^^^^^^^^^^^^^^^^^^^^^^^^^^^^^^^^^^^^^^^^^^^^^^^^^^^^^^^
  File "C:\Users\Oumaima\AppData\Local\Programs\Python\Python312\Lib\site-packages\django\core\mail\backends\smtp.py", line 128, in send_messages
    new_conn_created = self.open()
                       ^^^^^^^^^^^
  File "C:\Users\Oumaima\AppData\Local\Programs\Python\Python312\Lib\site-packages\django\core\mail\backends\smtp.py", line 95, in open
    self.connection.login(self.username, self.password)
  File "C:\Users\Oumaima\AppData\Local\Programs\Python\Python312\Lib\smtplib.py", line 750, in login
    raise last_exception
  File "C:\Users\Oumaima\AppData\Local\Programs\Python\Python312\Lib\smtplib.py", line 739, in login
    (code, resp) = self.auth(
                   ^^^^^^^^^^
  File "C:\Users\Oumaima\AppData\Local\Programs\Python\Python312\Lib\smtplib.py", line 662, in auth
    raise SMTPAuthenticationError(code, resp)
smtplib.SMTPAuthenticationError: (535, b'5.7.8 Username and Password not accepted. For more information, go to\n5.7.8  https://support.google.com/mail/?p=BadCredentials 5b1f17b1804b1-45b9c5c89f2sm299315565e9.14 - gsmtp')
Failed to send password reset email to 5
Traceback (most recent call last):
  File "C:\Users\Oumaima\AppData\Local\Programs\Python\Python312\Lib\site-packages\django\contrib\auth\forms.py", line 434, in send_mail
    email_message.send()
  File "C:\Users\Oumaima\AppData\Local\Programs\Python\Python312\Lib\site-packages\django\core\mail\message.py", line 307, in send
    return self.get_connection(fail_silently).send_messages([self])
           ^^^^^^^^^^^^^^^^^^^^^^^^^^^^^^^^^^^^^^^^^^^^^^^^^^^^^^^^
  File "C:\Users\Oumaima\AppData\Local\Programs\Python\Python312\Lib\site-packages\django\core\mail\backends\smtp.py", line 128, in send_messages
    new_conn_created = self.open()
                       ^^^^^^^^^^^
  File "C:\Users\Oumaima\AppData\Local\Programs\Python\Python312\Lib\site-packages\django\core\mail\backends\smtp.py", line 95, in open
    self.connection.login(self.username, self.password)
  File "C:\Users\Oumaima\AppData\Local\Programs\Python\Python312\Lib\smtplib.py", line 750, in login
    raise last_exception
  File "C:\Users\Oumaima\AppData\Local\Programs\Python\Python312\Lib\smtplib.py", line 739, in login
    (code, resp) = self.auth(
                   ^^^^^^^^^^
  File "C:\Users\Oumaima\AppData\Local\Programs\Python\Python312\Lib\smtplib.py", line 662, in auth
    raise SMTPAuthenticationError(code, resp)
smtplib.SMTPAuthenticationError: (535, b'5.7.8 Username and Password not accepted. For more information, go to\n5.7.8  https://support.google.com/mail/?p=BadCredentials ffacd0b85a97d-3e75215c51csm2602669f8f.0 - gsmtp')
Failed to send password reset email to 5
Traceback (most recent call last):
  File "C:\Users\Oumaima\AppData\Local\Programs\Python\Python312\Lib\site-packages\django\contrib\auth\forms.py", line 434, in send_mail
    email_message.send()
  File "C:\Users\Oumaima\AppData\Local\Programs\Python\Python312\Lib\site-packages\django\core\mail\message.py", line 307, in send
    return self.get_connection(fail_silently).send_messages([self])
           ^^^^^^^^^^^^^^^^^^^^^^^^^^^^^^^^^^^^^^^^^^^^^^^^^^^^^^^^
  File "C:\Users\Oumaima\AppData\Local\Programs\Python\Python312\Lib\site-packages\django\core\mail\backends\smtp.py", line 128, in send_messages
    new_conn_created = self.open()
                       ^^^^^^^^^^^
  File "C:\Users\Oumaima\AppData\Local\Programs\Python\Python312\Lib\site-packages\django\core\mail\backends\smtp.py", line 95, in open
    self.connection.login(self.username, self.password)
  File "C:\Users\Oumaima\AppData\Local\Programs\Python\Python312\Lib\smtplib.py", line 750, in login
    raise last_exception
  File "C:\Users\Oumaima\AppData\Local\Programs\Python\Python312\Lib\smtplib.py", line 739, in login
    (code, resp) = self.auth(
                   ^^^^^^^^^^
  File "C:\Users\Oumaima\AppData\Local\Programs\Python\Python312\Lib\smtplib.py", line 662, in auth
    raise SMTPAuthenticationError(code, resp)
smtplib.SMTPAuthenticationError: (535, b'5.7.8 Username and Password not accepted. For more information, go to\n5.7.8  https://support.google.com/mail/?p=BadCredentials 5b1f17b1804b1-45df16b2971sm9094915e9.7 - gsmtp')
Failed to send password reset email to 5
Traceback (most recent call last):
  File "C:\Users\Oumaima\AppData\Local\Programs\Python\Python312\Lib\site-packages\django\contrib\auth\forms.py", line 434, in send_mail
    email_message.send()
  File "C:\Users\Oumaima\AppData\Local\Programs\Python\Python312\Lib\site-packages\django\core\mail\message.py", line 307, in send
    return self.get_connection(fail_silently).send_messages([self])
           ^^^^^^^^^^^^^^^^^^^^^^^^^^^^^^^^^^^^^^^^^^^^^^^^^^^^^^^^
  File "C:\Users\Oumaima\AppData\Local\Programs\Python\Python312\Lib\site-packages\django\core\mail\backends\smtp.py", line 128, in send_messages
    new_conn_created = self.open()
                       ^^^^^^^^^^^
  File "C:\Users\Oumaima\AppData\Local\Programs\Python\Python312\Lib\site-packages\django\core\mail\backends\smtp.py", line 95, in open
    self.connection.login(self.username, self.password)
  File "C:\Users\Oumaima\AppData\Local\Programs\Python\Python312\Lib\smtplib.py", line 750, in login
    raise last_exception
  File "C:\Users\Oumaima\AppData\Local\Programs\Python\Python312\Lib\smtplib.py", line 739, in login
    (code, resp) = self.auth(
                   ^^^^^^^^^^
  File "C:\Users\Oumaima\AppData\Local\Programs\Python\Python312\Lib\smtplib.py", line 662, in auth
    raise SMTPAuthenticationError(code, resp)
smtplib.SMTPAuthenticationError: (535, b'5.7.8 Username and Password not accepted. For more information, go to\n5.7.8  https://support.google.com/mail/?p=BadCredentials ffacd0b85a97d-3e7521c99b9sm2767934f8f.15 - gsmtp')
You're accessing the development server over HTTPS, but it only supports HTTP.
You're accessing the development server over HTTPS, but it only supports HTTP.
You're accessing the development server over HTTPS, but it only supports HTTP.
You're accessing the development server over HTTPS, but it only supports HTTP.
You're accessing the development server over HTTPS, but it only supports HTTP.
You're accessing the development server over HTTPS, but it only supports HTTP.
You're accessing the development server over HTTPS, but it only supports HTTP.
You're accessing the development server over HTTPS, but it only supports HTTP.
You're accessing the development server over HTTPS, but it only supports HTTP.
You're accessing the development server over HTTPS, but it only supports HTTP.
You're accessing the development server over HTTPS, but it only supports HTTP.
You're accessing the development server over HTTPS, but it only supports HTTP.
You're accessing the development server over HTTPS, but it only supports HTTP.
You're accessing the development server over HTTPS, but it only supports HTTP.
Failed to send password reset email to 5
Traceback (most recent call last):
  File "C:\Users\Oumaima\AppData\Local\Programs\Python\Python312\Lib\site-packages\django\contrib\auth\forms.py", line 434, in send_mail
    email_message.send()
  File "C:\Users\Oumaima\AppData\Local\Programs\Python\Python312\Lib\site-packages\django\core\mail\message.py", line 307, in send
    return self.get_connection(fail_silently).send_messages([self])
           ^^^^^^^^^^^^^^^^^^^^^^^^^^^^^^^^^^^^^^^^^^^^^^^^^^^^^^^^
  File "C:\Users\Oumaima\AppData\Local\Programs\Python\Python312\Lib\site-packages\django\core\mail\backends\smtp.py", line 128, in send_messages
    new_conn_created = self.open()
                       ^^^^^^^^^^^
  File "C:\Users\Oumaima\AppData\Local\Programs\Python\Python312\Lib\site-packages\django\core\mail\backends\smtp.py", line 95, in open
    self.connection.login(self.username, self.password)
  File "C:\Users\Oumaima\AppData\Local\Programs\Python\Python312\Lib\smtplib.py", line 750, in login
    raise last_exception
  File "C:\Users\Oumaima\AppData\Local\Programs\Python\Python312\Lib\smtplib.py", line 739, in login
    (code, resp) = self.auth(
                   ^^^^^^^^^^
  File "C:\Users\Oumaima\AppData\Local\Programs\Python\Python312\Lib\smtplib.py", line 662, in auth
    raise SMTPAuthenticationError(code, resp)
smtplib.SMTPAuthenticationError: (535, b'5.7.8 Username and Password not accepted. For more information, go to\n5.7.8  https://support.google.com/mail/?p=BadCredentials ffacd0b85a97d-3e7522387acsm2779035f8f.40 - gsmtp')
Internal Server Error: /password_reset/
Traceback (most recent call last):
  File "C:\Users\Oumaima\AppData\Local\Programs\Python\Python312\Lib\site-packages\django\contrib\sites\models.py", line 39, in _get_site_by_request
    SITE_CACHE[host] = self.get(domain__iexact=host)
                       ^^^^^^^^^^^^^^^^^^^^^^^^^^^^^
  File "C:\Users\Oumaima\AppData\Local\Programs\Python\Python312\Lib\site-packages\django\db\models\manager.py", line 87, in manager_method
    return getattr(self.get_queryset(), name)(*args, **kwargs)
           ^^^^^^^^^^^^^^^^^^^^^^^^^^^^^^^^^^^^^^^^^^^^^^^^^^^
  File "C:\Users\Oumaima\AppData\Local\Programs\Python\Python312\Lib\site-packages\django\db\models\query.py", line 633, in get
    raise self.model.DoesNotExist(
django.contrib.sites.models.Site.DoesNotExist: Site matching query does not exist.

During handling of the above exception, another exception occurred:

Traceback (most recent call last):
  File "C:\Users\Oumaima\AppData\Local\Programs\Python\Python312\Lib\site-packages\django\core\handlers\exception.py", line 55, in inner
    response = get_response(request)
               ^^^^^^^^^^^^^^^^^^^^^
  File "C:\Users\Oumaima\AppData\Local\Programs\Python\Python312\Lib\site-packages\django\core\handlers\base.py", line 197, in _get_response
    response = wrapped_callback(request, *callback_args, **callback_kwargs)
               ^^^^^^^^^^^^^^^^^^^^^^^^^^^^^^^^^^^^^^^^^^^^^^^^^^^^^^^^^^^^
  File "C:\Users\Oumaima\AppData\Local\Programs\Python\Python312\Lib\site-packages\django\views\generic\base.py", line 105, in view
    return self.dispatch(request, *args, **kwargs)
           ^^^^^^^^^^^^^^^^^^^^^^^^^^^^^^^^^^^^^^^
  File "C:\Users\Oumaima\AppData\Local\Programs\Python\Python312\Lib\site-packages\django\utils\decorators.py", line 48, in _wrapper
    return bound_method(*args, **kwargs)
           ^^^^^^^^^^^^^^^^^^^^^^^^^^^^^
  File "C:\Users\Oumaima\AppData\Local\Programs\Python\Python312\Lib\site-packages\django\utils\decorators.py", line 48, in _wrapper
    return bound_method(*args, **kwargs)
           ^^^^^^^^^^^^^^^^^^^^^^^^^^^^^
  File "C:\Users\Oumaima\AppData\Local\Programs\Python\Python312\Lib\site-packages\django\utils\decorators.py", line 192, in _view_wrapper
    result = _process_exception(request, e)
             ^^^^^^^^^^^^^^^^^^^^^^^^^^^^^^
  File "C:\Users\Oumaima\AppData\Local\Programs\Python\Python312\Lib\site-packages\django\utils\decorators.py", line 190, in _view_wrapper
    response = view_func(request, *args, **kwargs)
               ^^^^^^^^^^^^^^^^^^^^^^^^^^^^^^^^^^^
  File "C:\Users\Oumaima\AppData\Local\Programs\Python\Python312\Lib\site-packages\django\contrib\auth\views.py", line 229, in dispatch
    return super().dispatch(*args, **kwargs)
           ^^^^^^^^^^^^^^^^^^^^^^^^^^^^^^^^^
  File "C:\Users\Oumaima\AppData\Local\Programs\Python\Python312\Lib\site-packages\django\views\generic\base.py", line 144, in dispatch
    return handler(request, *args, **kwargs)
           ^^^^^^^^^^^^^^^^^^^^^^^^^^^^^^^^^
  File "C:\Users\Oumaima\AppData\Local\Programs\Python\Python312\Lib\site-packages\django\views\generic\edit.py", line 151, in post
    return self.form_valid(form)
           ^^^^^^^^^^^^^^^^^^^^^
  File "C:\Users\Oumaima\AppData\Local\Programs\Python\Python312\Lib\site-packages\django\contrib\auth\views.py", line 242, in form_valid
    form.save(**opts)
  File "C:\Users\Oumaima\AppData\Local\Programs\Python\Python312\Lib\site-packages\django\contrib\auth\forms.py", line 479, in save
    current_site = get_current_site(request)
                   ^^^^^^^^^^^^^^^^^^^^^^^^^
  File "C:\Users\Oumaima\AppData\Local\Programs\Python\Python312\Lib\site-packages\django\contrib\sites\shortcuts.py", line 16, in get_current_site
    return Site.objects.get_current(request)
           ^^^^^^^^^^^^^^^^^^^^^^^^^^^^^^^^^
  File "C:\Users\Oumaima\AppData\Local\Programs\Python\Python312\Lib\site-packages\django\contrib\sites\models.py", line 61, in get_current
    return self._get_site_by_request(request)
           ^^^^^^^^^^^^^^^^^^^^^^^^^^^^^^^^^^
  File "C:\Users\Oumaima\AppData\Local\Programs\Python\Python312\Lib\site-packages\django\contrib\sites\models.py", line 45, in _get_site_by_request
    SITE_CACHE[domain] = self.get(domain__iexact=domain)
                         ^^^^^^^^^^^^^^^^^^^^^^^^^^^^^^^
  File "C:\Users\Oumaima\AppData\Local\Programs\Python\Python312\Lib\site-packages\django\db\models\manager.py", line 87, in manager_method
    return getattr(self.get_queryset(), name)(*args, **kwargs)
           ^^^^^^^^^^^^^^^^^^^^^^^^^^^^^^^^^^^^^^^^^^^^^^^^^^^
  File "C:\Users\Oumaima\AppData\Local\Programs\Python\Python312\Lib\site-packages\django\db\models\query.py", line 633, in get
    raise self.model.DoesNotExist(
django.contrib.sites.models.Site.DoesNotExist: Site matching query does not exist.
"POST /password_reset/ HTTP/1.1" 500 156575
You're accessing the development server over HTTPS, but it only supports HTTP.
You're accessing the development server over HTTPS, but it only supports HTTP.
Internal Server Error: /password_reset/
Traceback (most recent call last):
  File "C:\Users\Oumaima\AppData\Local\Programs\Python\Python312\Lib\site-packages\django\contrib\sites\models.py", line 39, in _get_site_by_request
    SITE_CACHE[host] = self.get(domain__iexact=host)
                       ^^^^^^^^^^^^^^^^^^^^^^^^^^^^^
  File "C:\Users\Oumaima\AppData\Local\Programs\Python\Python312\Lib\site-packages\django\db\models\manager.py", line 87, in manager_method
    return getattr(self.get_queryset(), name)(*args, **kwargs)
           ^^^^^^^^^^^^^^^^^^^^^^^^^^^^^^^^^^^^^^^^^^^^^^^^^^^
  File "C:\Users\Oumaima\AppData\Local\Programs\Python\Python312\Lib\site-packages\django\db\models\query.py", line 633, in get
    raise self.model.DoesNotExist(
django.contrib.sites.models.Site.DoesNotExist: Site matching query does not exist.

During handling of the above exception, another exception occurred:

Traceback (most recent call last):
  File "C:\Users\Oumaima\AppData\Local\Programs\Python\Python312\Lib\site-packages\django\core\handlers\exception.py", line 55, in inner
    response = get_response(request)
               ^^^^^^^^^^^^^^^^^^^^^
  File "C:\Users\Oumaima\AppData\Local\Programs\Python\Python312\Lib\site-packages\django\core\handlers\base.py", line 197, in _get_response
    response = wrapped_callback(request, *callback_args, **callback_kwargs)
               ^^^^^^^^^^^^^^^^^^^^^^^^^^^^^^^^^^^^^^^^^^^^^^^^^^^^^^^^^^^^
  File "C:\Users\Oumaima\AppData\Local\Programs\Python\Python312\Lib\site-packages\django\views\generic\base.py", line 105, in view
    return self.dispatch(request, *args, **kwargs)
           ^^^^^^^^^^^^^^^^^^^^^^^^^^^^^^^^^^^^^^^
  File "C:\Users\Oumaima\AppData\Local\Programs\Python\Python312\Lib\site-packages\django\utils\decorators.py", line 48, in _wrapper
    return bound_method(*args, **kwargs)
           ^^^^^^^^^^^^^^^^^^^^^^^^^^^^^
  File "C:\Users\Oumaima\AppData\Local\Programs\Python\Python312\Lib\site-packages\django\utils\decorators.py", line 48, in _wrapper
    return bound_method(*args, **kwargs)
           ^^^^^^^^^^^^^^^^^^^^^^^^^^^^^
  File "C:\Users\Oumaima\AppData\Local\Programs\Python\Python312\Lib\site-packages\django\utils\decorators.py", line 192, in _view_wrapper
    result = _process_exception(request, e)
             ^^^^^^^^^^^^^^^^^^^^^^^^^^^^^^
  File "C:\Users\Oumaima\AppData\Local\Programs\Python\Python312\Lib\site-packages\django\utils\decorators.py", line 190, in _view_wrapper
    response = view_func(request, *args, **kwargs)
               ^^^^^^^^^^^^^^^^^^^^^^^^^^^^^^^^^^^
  File "C:\Users\Oumaima\AppData\Local\Programs\Python\Python312\Lib\site-packages\django\contrib\auth\views.py", line 229, in dispatch
    return super().dispatch(*args, **kwargs)
           ^^^^^^^^^^^^^^^^^^^^^^^^^^^^^^^^^
  File "C:\Users\Oumaima\AppData\Local\Programs\Python\Python312\Lib\site-packages\django\views\generic\base.py", line 144, in dispatch
    return handler(request, *args, **kwargs)
           ^^^^^^^^^^^^^^^^^^^^^^^^^^^^^^^^^
  File "C:\Users\Oumaima\AppData\Local\Programs\Python\Python312\Lib\site-packages\django\views\generic\edit.py", line 151, in post
    return self.form_valid(form)
           ^^^^^^^^^^^^^^^^^^^^^
  File "C:\Users\Oumaima\AppData\Local\Programs\Python\Python312\Lib\site-packages\django\contrib\auth\views.py", line 242, in form_valid
    form.save(**opts)
  File "C:\Users\Oumaima\AppData\Local\Programs\Python\Python312\Lib\site-packages\django\contrib\auth\forms.py", line 479, in save
    current_site = get_current_site(request)
                   ^^^^^^^^^^^^^^^^^^^^^^^^^
  File "C:\Users\Oumaima\AppData\Local\Programs\Python\Python312\Lib\site-packages\django\contrib\sites\shortcuts.py", line 16, in get_current_site
    return Site.objects.get_current(request)
           ^^^^^^^^^^^^^^^^^^^^^^^^^^^^^^^^^
  File "C:\Users\Oumaima\AppData\Local\Programs\Python\Python312\Lib\site-packages\django\contrib\sites\models.py", line 61, in get_current
    return self._get_site_by_request(request)
           ^^^^^^^^^^^^^^^^^^^^^^^^^^^^^^^^^^
  File "C:\Users\Oumaima\AppData\Local\Programs\Python\Python312\Lib\site-packages\django\contrib\sites\models.py", line 45, in _get_site_by_request
    SITE_CACHE[domain] = self.get(domain__iexact=domain)
                         ^^^^^^^^^^^^^^^^^^^^^^^^^^^^^^^
  File "C:\Users\Oumaima\AppData\Local\Programs\Python\Python312\Lib\site-packages\django\db\models\manager.py", line 87, in manager_method
    return getattr(self.get_queryset(), name)(*args, **kwargs)
           ^^^^^^^^^^^^^^^^^^^^^^^^^^^^^^^^^^^^^^^^^^^^^^^^^^^
  File "C:\Users\Oumaima\AppData\Local\Programs\Python\Python312\Lib\site-packages\django\db\models\query.py", line 633, in get
    raise self.model.DoesNotExist(
django.contrib.sites.models.Site.DoesNotExist: Site matching query does not exist.
"POST /password_reset/ HTTP/1.1" 500 156580
Internal Server Error: /password_reset/
Traceback (most recent call last):
  File "C:\Users\Oumaima\AppData\Local\Programs\Python\Python312\Lib\site-packages\django\contrib\sites\models.py", line 39, in _get_site_by_request
    SITE_CACHE[host] = self.get(domain__iexact=host)
                       ^^^^^^^^^^^^^^^^^^^^^^^^^^^^^
  File "C:\Users\Oumaima\AppData\Local\Programs\Python\Python312\Lib\site-packages\django\db\models\manager.py", line 87, in manager_method
    return getattr(self.get_queryset(), name)(*args, **kwargs)
           ^^^^^^^^^^^^^^^^^^^^^^^^^^^^^^^^^^^^^^^^^^^^^^^^^^^
  File "C:\Users\Oumaima\AppData\Local\Programs\Python\Python312\Lib\site-packages\django\db\models\query.py", line 633, in get
    raise self.model.DoesNotExist(
django.contrib.sites.models.Site.DoesNotExist: Site matching query does not exist.

During handling of the above exception, another exception occurred:

Traceback (most recent call last):
  File "C:\Users\Oumaima\AppData\Local\Programs\Python\Python312\Lib\site-packages\django\core\handlers\exception.py", line 55, in inner
    response = get_response(request)
               ^^^^^^^^^^^^^^^^^^^^^
  File "C:\Users\Oumaima\AppData\Local\Programs\Python\Python312\Lib\site-packages\django\core\handlers\base.py", line 197, in _get_response
    response = wrapped_callback(request, *callback_args, **callback_kwargs)
               ^^^^^^^^^^^^^^^^^^^^^^^^^^^^^^^^^^^^^^^^^^^^^^^^^^^^^^^^^^^^
  File "C:\Users\Oumaima\AppData\Local\Programs\Python\Python312\Lib\site-packages\django\views\generic\base.py", line 105, in view
    return self.dispatch(request, *args, **kwargs)
           ^^^^^^^^^^^^^^^^^^^^^^^^^^^^^^^^^^^^^^^
  File "C:\Users\Oumaima\AppData\Local\Programs\Python\Python312\Lib\site-packages\django\utils\decorators.py", line 48, in _wrapper
    return bound_method(*args, **kwargs)
           ^^^^^^^^^^^^^^^^^^^^^^^^^^^^^
  File "C:\Users\Oumaima\AppData\Local\Programs\Python\Python312\Lib\site-packages\django\utils\decorators.py", line 48, in _wrapper
    return bound_method(*args, **kwargs)
           ^^^^^^^^^^^^^^^^^^^^^^^^^^^^^
  File "C:\Users\Oumaima\AppData\Local\Programs\Python\Python312\Lib\site-packages\django\utils\decorators.py", line 192, in _view_wrapper
    result = _process_exception(request, e)
             ^^^^^^^^^^^^^^^^^^^^^^^^^^^^^^
  File "C:\Users\Oumaima\AppData\Local\Programs\Python\Python312\Lib\site-packages\django\utils\decorators.py", line 190, in _view_wrapper
    response = view_func(request, *args, **kwargs)
               ^^^^^^^^^^^^^^^^^^^^^^^^^^^^^^^^^^^
  File "C:\Users\Oumaima\AppData\Local\Programs\Python\Python312\Lib\site-packages\django\contrib\auth\views.py", line 229, in dispatch
    return super().dispatch(*args, **kwargs)
           ^^^^^^^^^^^^^^^^^^^^^^^^^^^^^^^^^
  File "C:\Users\Oumaima\AppData\Local\Programs\Python\Python312\Lib\site-packages\django\views\generic\base.py", line 144, in dispatch
    return handler(request, *args, **kwargs)
           ^^^^^^^^^^^^^^^^^^^^^^^^^^^^^^^^^
  File "C:\Users\Oumaima\AppData\Local\Programs\Python\Python312\Lib\site-packages\django\views\generic\edit.py", line 151, in post
    return self.form_valid(form)
           ^^^^^^^^^^^^^^^^^^^^^
  File "C:\Users\Oumaima\AppData\Local\Programs\Python\Python312\Lib\site-packages\django\contrib\auth\views.py", line 242, in form_valid
    form.save(**opts)
  File "C:\Users\Oumaima\AppData\Local\Programs\Python\Python312\Lib\site-packages\django\contrib\auth\forms.py", line 479, in save
    current_site = get_current_site(request)
                   ^^^^^^^^^^^^^^^^^^^^^^^^^
  File "C:\Users\Oumaima\AppData\Local\Programs\Python\Python312\Lib\site-packages\django\contrib\sites\shortcuts.py", line 16, in get_current_site
    return Site.objects.get_current(request)
           ^^^^^^^^^^^^^^^^^^^^^^^^^^^^^^^^^
  File "C:\Users\Oumaima\AppData\Local\Programs\Python\Python312\Lib\site-packages\django\contrib\sites\models.py", line 61, in get_current
    return self._get_site_by_request(request)
           ^^^^^^^^^^^^^^^^^^^^^^^^^^^^^^^^^^
  File "C:\Users\Oumaima\AppData\Local\Programs\Python\Python312\Lib\site-packages\django\contrib\sites\models.py", line 45, in _get_site_by_request
    SITE_CACHE[domain] = self.get(domain__iexact=domain)
                         ^^^^^^^^^^^^^^^^^^^^^^^^^^^^^^^
  File "C:\Users\Oumaima\AppData\Local\Programs\Python\Python312\Lib\site-packages\django\db\models\manager.py", line 87, in manager_method
    return getattr(self.get_queryset(), name)(*args, **kwargs)
           ^^^^^^^^^^^^^^^^^^^^^^^^^^^^^^^^^^^^^^^^^^^^^^^^^^^
  File "C:\Users\Oumaima\AppData\Local\Programs\Python\Python312\Lib\site-packages\django\db\models\query.py", line 633, in get
    raise self.model.DoesNotExist(
django.contrib.sites.models.Site.DoesNotExist: Site matching query does not exist.
"POST /password_reset/ HTTP/1.1" 500 156646
Internal Server Error: /admin/login/
Traceback (most recent call last):
  File "C:\Users\Oumaima\AppData\Local\Programs\Python\Python312\Lib\site-packages\django\contrib\sites\models.py", line 39, in _get_site_by_request
    SITE_CACHE[host] = self.get(domain__iexact=host)
                       ^^^^^^^^^^^^^^^^^^^^^^^^^^^^^
  File "C:\Users\Oumaima\AppData\Local\Programs\Python\Python312\Lib\site-packages\django\db\models\manager.py", line 87, in manager_method
    return getattr(self.get_queryset(), name)(*args, **kwargs)
           ^^^^^^^^^^^^^^^^^^^^^^^^^^^^^^^^^^^^^^^^^^^^^^^^^^^
  File "C:\Users\Oumaima\AppData\Local\Programs\Python\Python312\Lib\site-packages\django\db\models\query.py", line 633, in get
    raise self.model.DoesNotExist(
django.contrib.sites.models.Site.DoesNotExist: Site matching query does not exist.

During handling of the above exception, another exception occurred:

Traceback (most recent call last):
  File "C:\Users\Oumaima\AppData\Local\Programs\Python\Python312\Lib\site-packages\django\core\handlers\exception.py", line 55, in inner
    response = get_response(request)
               ^^^^^^^^^^^^^^^^^^^^^
  File "C:\Users\Oumaima\AppData\Local\Programs\Python\Python312\Lib\site-packages\django\core\handlers\base.py", line 197, in _get_response
    response = wrapped_callback(request, *callback_args, **callback_kwargs)
               ^^^^^^^^^^^^^^^^^^^^^^^^^^^^^^^^^^^^^^^^^^^^^^^^^^^^^^^^^^^^
  File "C:\Users\Oumaima\AppData\Local\Programs\Python\Python312\Lib\site-packages\django\utils\decorators.py", line 48, in _wrapper
    return bound_method(*args, **kwargs)
           ^^^^^^^^^^^^^^^^^^^^^^^^^^^^^
  File "C:\Users\Oumaima\AppData\Local\Programs\Python\Python312\Lib\site-packages\django\views\decorators\cache.py", line 80, in _view_wrapper
    response = view_func(request, *args, **kwargs)
               ^^^^^^^^^^^^^^^^^^^^^^^^^^^^^^^^^^^
  File "C:\Users\Oumaima\AppData\Local\Programs\Python\Python312\Lib\site-packages\django\contrib\admin\sites.py", line 449, in login
    return LoginView.as_view(**defaults)(request)
           ^^^^^^^^^^^^^^^^^^^^^^^^^^^^^^^^^^^^^^
  File "C:\Users\Oumaima\AppData\Local\Programs\Python\Python312\Lib\site-packages\django\views\generic\base.py", line 105, in view
    return self.dispatch(request, *args, **kwargs)
           ^^^^^^^^^^^^^^^^^^^^^^^^^^^^^^^^^^^^^^^
  File "C:\Users\Oumaima\AppData\Local\Programs\Python\Python312\Lib\site-packages\django\utils\decorators.py", line 48, in _wrapper
    return bound_method(*args, **kwargs)
           ^^^^^^^^^^^^^^^^^^^^^^^^^^^^^
  File "C:\Users\Oumaima\AppData\Local\Programs\Python\Python312\Lib\site-packages\django\utils\decorators.py", line 48, in _wrapper
    return bound_method(*args, **kwargs)
           ^^^^^^^^^^^^^^^^^^^^^^^^^^^^^
  File "C:\Users\Oumaima\AppData\Local\Programs\Python\Python312\Lib\site-packages\django\views\decorators\debug.py", line 143, in sensitive_post_parameters_wrapper
    return view(request, *args, **kwargs)
           ^^^^^^^^^^^^^^^^^^^^^^^^^^^^^^
  File "C:\Users\Oumaima\AppData\Local\Programs\Python\Python312\Lib\site-packages\django\utils\decorators.py", line 48, in _wrapper
    return bound_method(*args, **kwargs)
           ^^^^^^^^^^^^^^^^^^^^^^^^^^^^^
  File "C:\Users\Oumaima\AppData\Local\Programs\Python\Python312\Lib\site-packages\django\utils\decorators.py", line 192, in _view_wrapper
    result = _process_exception(request, e)
             ^^^^^^^^^^^^^^^^^^^^^^^^^^^^^^
  File "C:\Users\Oumaima\AppData\Local\Programs\Python\Python312\Lib\site-packages\django\utils\decorators.py", line 190, in _view_wrapper
    response = view_func(request, *args, **kwargs)
               ^^^^^^^^^^^^^^^^^^^^^^^^^^^^^^^^^^^
  File "C:\Users\Oumaima\AppData\Local\Programs\Python\Python312\Lib\site-packages\django\utils\decorators.py", line 48, in _wrapper
    return bound_method(*args, **kwargs)
           ^^^^^^^^^^^^^^^^^^^^^^^^^^^^^
  File "C:\Users\Oumaima\AppData\Local\Programs\Python\Python312\Lib\site-packages\django\views\decorators\cache.py", line 80, in _view_wrapper
    response = view_func(request, *args, **kwargs)
               ^^^^^^^^^^^^^^^^^^^^^^^^^^^^^^^^^^^
  File "C:\Users\Oumaima\AppData\Local\Programs\Python\Python312\Lib\site-packages\django\contrib\auth\views.py", line 89, in dispatch
    return super().dispatch(request, *args, **kwargs)
           ^^^^^^^^^^^^^^^^^^^^^^^^^^^^^^^^^^^^^^^^^^
  File "C:\Users\Oumaima\AppData\Local\Programs\Python\Python312\Lib\site-packages\django\views\generic\base.py", line 144, in dispatch
    return handler(request, *args, **kwargs)
           ^^^^^^^^^^^^^^^^^^^^^^^^^^^^^^^^^
  File "C:\Users\Oumaima\AppData\Local\Programs\Python\Python312\Lib\site-packages\django\views\generic\edit.py", line 142, in get
    return self.render_to_response(self.get_context_data())
                                   ^^^^^^^^^^^^^^^^^^^^^^^
  File "C:\Users\Oumaima\AppData\Local\Programs\Python\Python312\Lib\site-packages\django\contrib\auth\views.py", line 113, in get_context_data
    current_site = get_current_site(self.request)
                   ^^^^^^^^^^^^^^^^^^^^^^^^^^^^^^
  File "C:\Users\Oumaima\AppData\Local\Programs\Python\Python312\Lib\site-packages\django\contrib\sites\shortcuts.py", line 16, in get_current_site
    return Site.objects.get_current(request)
           ^^^^^^^^^^^^^^^^^^^^^^^^^^^^^^^^^
  File "C:\Users\Oumaima\AppData\Local\Programs\Python\Python312\Lib\site-packages\django\contrib\sites\models.py", line 61, in get_current
    return self._get_site_by_request(request)
           ^^^^^^^^^^^^^^^^^^^^^^^^^^^^^^^^^^
  File "C:\Users\Oumaima\AppData\Local\Programs\Python\Python312\Lib\site-packages\django\contrib\sites\models.py", line 45, in _get_site_by_request
    SITE_CACHE[domain] = self.get(domain__iexact=domain)
                         ^^^^^^^^^^^^^^^^^^^^^^^^^^^^^^^
  File "C:\Users\Oumaima\AppData\Local\Programs\Python\Python312\Lib\site-packages\django\db\models\manager.py", line 87, in manager_method
    return getattr(self.get_queryset(), name)(*args, **kwargs)
           ^^^^^^^^^^^^^^^^^^^^^^^^^^^^^^^^^^^^^^^^^^^^^^^^^^^
  File "C:\Users\Oumaima\AppData\Local\Programs\Python\Python312\Lib\site-packages\django\db\models\query.py", line 633, in get
    raise self.model.DoesNotExist(
django.contrib.sites.models.Site.DoesNotExist: Site matching query does not exist.
"GET /admin/login/?next=/admin/ HTTP/1.1" 500 186065
Internal Server Error: /password_reset/
Traceback (most recent call last):
  File "C:\Users\Oumaima\AppData\Local\Programs\Python\Python312\Lib\site-packages\django\contrib\sites\models.py", line 39, in _get_site_by_request
    SITE_CACHE[host] = self.get(domain__iexact=host)
                       ^^^^^^^^^^^^^^^^^^^^^^^^^^^^^
  File "C:\Users\Oumaima\AppData\Local\Programs\Python\Python312\Lib\site-packages\django\db\models\manager.py", line 87, in manager_method
    return getattr(self.get_queryset(), name)(*args, **kwargs)
           ^^^^^^^^^^^^^^^^^^^^^^^^^^^^^^^^^^^^^^^^^^^^^^^^^^^
  File "C:\Users\Oumaima\AppData\Local\Programs\Python\Python312\Lib\site-packages\django\db\models\query.py", line 633, in get
    raise self.model.DoesNotExist(
django.contrib.sites.models.Site.DoesNotExist: Site matching query does not exist.

During handling of the above exception, another exception occurred:

Traceback (most recent call last):
  File "C:\Users\Oumaima\AppData\Local\Programs\Python\Python312\Lib\site-packages\django\core\handlers\exception.py", line 55, in inner
    response = get_response(request)
               ^^^^^^^^^^^^^^^^^^^^^
  File "C:\Users\Oumaima\AppData\Local\Programs\Python\Python312\Lib\site-packages\django\core\handlers\base.py", line 197, in _get_response
    response = wrapped_callback(request, *callback_args, **callback_kwargs)
               ^^^^^^^^^^^^^^^^^^^^^^^^^^^^^^^^^^^^^^^^^^^^^^^^^^^^^^^^^^^^
  File "C:\Users\Oumaima\AppData\Local\Programs\Python\Python312\Lib\site-packages\django\views\generic\base.py", line 105, in view
    return self.dispatch(request, *args, **kwargs)
           ^^^^^^^^^^^^^^^^^^^^^^^^^^^^^^^^^^^^^^^
  File "C:\Users\Oumaima\AppData\Local\Programs\Python\Python312\Lib\site-packages\django\utils\decorators.py", line 48, in _wrapper
    return bound_method(*args, **kwargs)
           ^^^^^^^^^^^^^^^^^^^^^^^^^^^^^
  File "C:\Users\Oumaima\AppData\Local\Programs\Python\Python312\Lib\site-packages\django\utils\decorators.py", line 48, in _wrapper
    return bound_method(*args, **kwargs)
           ^^^^^^^^^^^^^^^^^^^^^^^^^^^^^
  File "C:\Users\Oumaima\AppData\Local\Programs\Python\Python312\Lib\site-packages\django\utils\decorators.py", line 192, in _view_wrapper
    result = _process_exception(request, e)
             ^^^^^^^^^^^^^^^^^^^^^^^^^^^^^^
  File "C:\Users\Oumaima\AppData\Local\Programs\Python\Python312\Lib\site-packages\django\utils\decorators.py", line 190, in _view_wrapper
    response = view_func(request, *args, **kwargs)
               ^^^^^^^^^^^^^^^^^^^^^^^^^^^^^^^^^^^
  File "C:\Users\Oumaima\AppData\Local\Programs\Python\Python312\Lib\site-packages\django\contrib\auth\views.py", line 229, in dispatch
    return super().dispatch(*args, **kwargs)
           ^^^^^^^^^^^^^^^^^^^^^^^^^^^^^^^^^
  File "C:\Users\Oumaima\AppData\Local\Programs\Python\Python312\Lib\site-packages\django\views\generic\base.py", line 144, in dispatch
    return handler(request, *args, **kwargs)
           ^^^^^^^^^^^^^^^^^^^^^^^^^^^^^^^^^
  File "C:\Users\Oumaima\AppData\Local\Programs\Python\Python312\Lib\site-packages\django\views\generic\edit.py", line 151, in post
    return self.form_valid(form)
           ^^^^^^^^^^^^^^^^^^^^^
  File "C:\Users\Oumaima\AppData\Local\Programs\Python\Python312\Lib\site-packages\django\contrib\auth\views.py", line 242, in form_valid
    form.save(**opts)
  File "C:\Users\Oumaima\AppData\Local\Programs\Python\Python312\Lib\site-packages\django\contrib\auth\forms.py", line 479, in save
    current_site = get_current_site(request)
                   ^^^^^^^^^^^^^^^^^^^^^^^^^
  File "C:\Users\Oumaima\AppData\Local\Programs\Python\Python312\Lib\site-packages\django\contrib\sites\shortcuts.py", line 16, in get_current_site
    return Site.objects.get_current(request)
           ^^^^^^^^^^^^^^^^^^^^^^^^^^^^^^^^^
  File "C:\Users\Oumaima\AppData\Local\Programs\Python\Python312\Lib\site-packages\django\contrib\sites\models.py", line 61, in get_current
    return self._get_site_by_request(request)
           ^^^^^^^^^^^^^^^^^^^^^^^^^^^^^^^^^^
  File "C:\Users\Oumaima\AppData\Local\Programs\Python\Python312\Lib\site-packages\django\contrib\sites\models.py", line 45, in _get_site_by_request
    SITE_CACHE[domain] = self.get(domain__iexact=domain)
                         ^^^^^^^^^^^^^^^^^^^^^^^^^^^^^^^
  File "C:\Users\Oumaima\AppData\Local\Programs\Python\Python312\Lib\site-packages\django\db\models\manager.py", line 87, in manager_method
    return getattr(self.get_queryset(), name)(*args, **kwargs)
           ^^^^^^^^^^^^^^^^^^^^^^^^^^^^^^^^^^^^^^^^^^^^^^^^^^^
  File "C:\Users\Oumaima\AppData\Local\Programs\Python\Python312\Lib\site-packages\django\db\models\query.py", line 633, in get
    raise self.model.DoesNotExist(
django.contrib.sites.models.Site.DoesNotExist: Site matching query does not exist.
"POST /password_reset/ HTTP/1.1" 500 156646
Internal Server Error: /password_reset/
Traceback (most recent call last):
  File "C:\Users\Oumaima\AppData\Local\Programs\Python\Python312\Lib\site-packages\django\contrib\sites\models.py", line 39, in _get_site_by_request
    SITE_CACHE[host] = self.get(domain__iexact=host)
                       ^^^^^^^^^^^^^^^^^^^^^^^^^^^^^
  File "C:\Users\Oumaima\AppData\Local\Programs\Python\Python312\Lib\site-packages\django\db\models\manager.py", line 87, in manager_method
    return getattr(self.get_queryset(), name)(*args, **kwargs)
           ^^^^^^^^^^^^^^^^^^^^^^^^^^^^^^^^^^^^^^^^^^^^^^^^^^^
  File "C:\Users\Oumaima\AppData\Local\Programs\Python\Python312\Lib\site-packages\django\db\models\query.py", line 633, in get
    raise self.model.DoesNotExist(
django.contrib.sites.models.Site.DoesNotExist: Site matching query does not exist.

During handling of the above exception, another exception occurred:

Traceback (most recent call last):
  File "C:\Users\Oumaima\AppData\Local\Programs\Python\Python312\Lib\site-packages\django\core\handlers\exception.py", line 55, in inner
    response = get_response(request)
               ^^^^^^^^^^^^^^^^^^^^^
  File "C:\Users\Oumaima\AppData\Local\Programs\Python\Python312\Lib\site-packages\django\core\handlers\base.py", line 197, in _get_response
    response = wrapped_callback(request, *callback_args, **callback_kwargs)
               ^^^^^^^^^^^^^^^^^^^^^^^^^^^^^^^^^^^^^^^^^^^^^^^^^^^^^^^^^^^^
  File "C:\Users\Oumaima\AppData\Local\Programs\Python\Python312\Lib\site-packages\django\views\generic\base.py", line 105, in view
    return self.dispatch(request, *args, **kwargs)
           ^^^^^^^^^^^^^^^^^^^^^^^^^^^^^^^^^^^^^^^
  File "C:\Users\Oumaima\AppData\Local\Programs\Python\Python312\Lib\site-packages\django\utils\decorators.py", line 48, in _wrapper
    return bound_method(*args, **kwargs)
           ^^^^^^^^^^^^^^^^^^^^^^^^^^^^^
  File "C:\Users\Oumaima\AppData\Local\Programs\Python\Python312\Lib\site-packages\django\utils\decorators.py", line 48, in _wrapper
    return bound_method(*args, **kwargs)
           ^^^^^^^^^^^^^^^^^^^^^^^^^^^^^
  File "C:\Users\Oumaima\AppData\Local\Programs\Python\Python312\Lib\site-packages\django\utils\decorators.py", line 192, in _view_wrapper
    result = _process_exception(request, e)
             ^^^^^^^^^^^^^^^^^^^^^^^^^^^^^^
  File "C:\Users\Oumaima\AppData\Local\Programs\Python\Python312\Lib\site-packages\django\utils\decorators.py", line 190, in _view_wrapper
    response = view_func(request, *args, **kwargs)
               ^^^^^^^^^^^^^^^^^^^^^^^^^^^^^^^^^^^
  File "C:\Users\Oumaima\AppData\Local\Programs\Python\Python312\Lib\site-packages\django\contrib\auth\views.py", line 229, in dispatch
    return super().dispatch(*args, **kwargs)
           ^^^^^^^^^^^^^^^^^^^^^^^^^^^^^^^^^
  File "C:\Users\Oumaima\AppData\Local\Programs\Python\Python312\Lib\site-packages\django\views\generic\base.py", line 144, in dispatch
    return handler(request, *args, **kwargs)
           ^^^^^^^^^^^^^^^^^^^^^^^^^^^^^^^^^
  File "C:\Users\Oumaima\AppData\Local\Programs\Python\Python312\Lib\site-packages\django\views\generic\edit.py", line 151, in post
    return self.form_valid(form)
           ^^^^^^^^^^^^^^^^^^^^^
  File "C:\Users\Oumaima\AppData\Local\Programs\Python\Python312\Lib\site-packages\django\contrib\auth\views.py", line 242, in form_valid
    form.save(**opts)
  File "C:\Users\Oumaima\AppData\Local\Programs\Python\Python312\Lib\site-packages\django\contrib\auth\forms.py", line 479, in save
    current_site = get_current_site(request)
                   ^^^^^^^^^^^^^^^^^^^^^^^^^
  File "C:\Users\Oumaima\AppData\Local\Programs\Python\Python312\Lib\site-packages\django\contrib\sites\shortcuts.py", line 16, in get_current_site
    return Site.objects.get_current(request)
           ^^^^^^^^^^^^^^^^^^^^^^^^^^^^^^^^^
  File "C:\Users\Oumaima\AppData\Local\Programs\Python\Python312\Lib\site-packages\django\contrib\sites\models.py", line 61, in get_current
    return self._get_site_by_request(request)
           ^^^^^^^^^^^^^^^^^^^^^^^^^^^^^^^^^^
  File "C:\Users\Oumaima\AppData\Local\Programs\Python\Python312\Lib\site-packages\django\contrib\sites\models.py", line 45, in _get_site_by_request
    SITE_CACHE[domain] = self.get(domain__iexact=domain)
                         ^^^^^^^^^^^^^^^^^^^^^^^^^^^^^^^
  File "C:\Users\Oumaima\AppData\Local\Programs\Python\Python312\Lib\site-packages\django\db\models\manager.py", line 87, in manager_method
    return getattr(self.get_queryset(), name)(*args, **kwargs)
           ^^^^^^^^^^^^^^^^^^^^^^^^^^^^^^^^^^^^^^^^^^^^^^^^^^^
  File "C:\Users\Oumaima\AppData\Local\Programs\Python\Python312\Lib\site-packages\django\db\models\query.py", line 633, in get
    raise self.model.DoesNotExist(
django.contrib.sites.models.Site.DoesNotExist: Site matching query does not exist.
"POST /password_reset/ HTTP/1.1" 500 156646
Internal Server Error: /password_reset/
Traceback (most recent call last):
  File "C:\Users\Oumaima\AppData\Local\Programs\Python\Python312\Lib\site-packages\django\contrib\sites\models.py", line 39, in _get_site_by_request
    SITE_CACHE[host] = self.get(domain__iexact=host)
                       ^^^^^^^^^^^^^^^^^^^^^^^^^^^^^
  File "C:\Users\Oumaima\AppData\Local\Programs\Python\Python312\Lib\site-packages\django\db\models\manager.py", line 87, in manager_method
    return getattr(self.get_queryset(), name)(*args, **kwargs)
           ^^^^^^^^^^^^^^^^^^^^^^^^^^^^^^^^^^^^^^^^^^^^^^^^^^^
  File "C:\Users\Oumaima\AppData\Local\Programs\Python\Python312\Lib\site-packages\django\db\models\query.py", line 633, in get
    raise self.model.DoesNotExist(
django.contrib.sites.models.Site.DoesNotExist: Site matching query does not exist.

During handling of the above exception, another exception occurred:

Traceback (most recent call last):
  File "C:\Users\Oumaima\AppData\Local\Programs\Python\Python312\Lib\site-packages\django\core\handlers\exception.py", line 55, in inner
    response = get_response(request)
               ^^^^^^^^^^^^^^^^^^^^^
  File "C:\Users\Oumaima\AppData\Local\Programs\Python\Python312\Lib\site-packages\django\core\handlers\base.py", line 197, in _get_response
    response = wrapped_callback(request, *callback_args, **callback_kwargs)
               ^^^^^^^^^^^^^^^^^^^^^^^^^^^^^^^^^^^^^^^^^^^^^^^^^^^^^^^^^^^^
  File "C:\Users\Oumaima\AppData\Local\Programs\Python\Python312\Lib\site-packages\django\views\generic\base.py", line 105, in view
    return self.dispatch(request, *args, **kwargs)
           ^^^^^^^^^^^^^^^^^^^^^^^^^^^^^^^^^^^^^^^
  File "C:\Users\Oumaima\AppData\Local\Programs\Python\Python312\Lib\site-packages\django\utils\decorators.py", line 48, in _wrapper
    return bound_method(*args, **kwargs)
           ^^^^^^^^^^^^^^^^^^^^^^^^^^^^^
  File "C:\Users\Oumaima\AppData\Local\Programs\Python\Python312\Lib\site-packages\django\utils\decorators.py", line 48, in _wrapper
    return bound_method(*args, **kwargs)
           ^^^^^^^^^^^^^^^^^^^^^^^^^^^^^
  File "C:\Users\Oumaima\AppData\Local\Programs\Python\Python312\Lib\site-packages\django\utils\decorators.py", line 192, in _view_wrapper
    result = _process_exception(request, e)
             ^^^^^^^^^^^^^^^^^^^^^^^^^^^^^^
  File "C:\Users\Oumaima\AppData\Local\Programs\Python\Python312\Lib\site-packages\django\utils\decorators.py", line 190, in _view_wrapper
    response = view_func(request, *args, **kwargs)
               ^^^^^^^^^^^^^^^^^^^^^^^^^^^^^^^^^^^
  File "C:\Users\Oumaima\AppData\Local\Programs\Python\Python312\Lib\site-packages\django\contrib\auth\views.py", line 229, in dispatch
    return super().dispatch(*args, **kwargs)
           ^^^^^^^^^^^^^^^^^^^^^^^^^^^^^^^^^
  File "C:\Users\Oumaima\AppData\Local\Programs\Python\Python312\Lib\site-packages\django\views\generic\base.py", line 144, in dispatch
    return handler(request, *args, **kwargs)
           ^^^^^^^^^^^^^^^^^^^^^^^^^^^^^^^^^
  File "C:\Users\Oumaima\AppData\Local\Programs\Python\Python312\Lib\site-packages\django\views\generic\edit.py", line 151, in post
    return self.form_valid(form)
           ^^^^^^^^^^^^^^^^^^^^^
  File "C:\Users\Oumaima\AppData\Local\Programs\Python\Python312\Lib\site-packages\django\contrib\auth\views.py", line 242, in form_valid
    form.save(**opts)
  File "C:\Users\Oumaima\AppData\Local\Programs\Python\Python312\Lib\site-packages\django\contrib\auth\forms.py", line 479, in save
    current_site = get_current_site(request)
                   ^^^^^^^^^^^^^^^^^^^^^^^^^
  File "C:\Users\Oumaima\AppData\Local\Programs\Python\Python312\Lib\site-packages\django\contrib\sites\shortcuts.py", line 16, in get_current_site
    return Site.objects.get_current(request)
           ^^^^^^^^^^^^^^^^^^^^^^^^^^^^^^^^^
  File "C:\Users\Oumaima\AppData\Local\Programs\Python\Python312\Lib\site-packages\django\contrib\sites\models.py", line 61, in get_current
    return self._get_site_by_request(request)
           ^^^^^^^^^^^^^^^^^^^^^^^^^^^^^^^^^^
  File "C:\Users\Oumaima\AppData\Local\Programs\Python\Python312\Lib\site-packages\django\contrib\sites\models.py", line 45, in _get_site_by_request
    SITE_CACHE[domain] = self.get(domain__iexact=domain)
                         ^^^^^^^^^^^^^^^^^^^^^^^^^^^^^^^
  File "C:\Users\Oumaima\AppData\Local\Programs\Python\Python312\Lib\site-packages\django\db\models\manager.py", line 87, in manager_method
    return getattr(self.get_queryset(), name)(*args, **kwargs)
           ^^^^^^^^^^^^^^^^^^^^^^^^^^^^^^^^^^^^^^^^^^^^^^^^^^^
  File "C:\Users\Oumaima\AppData\Local\Programs\Python\Python312\Lib\site-packages\django\db\models\query.py", line 633, in get
    raise self.model.DoesNotExist(
django.contrib.sites.models.Site.DoesNotExist: Site matching query does not exist.
"POST /password_reset/ HTTP/1.1" 500 156646
You're accessing the development server over HTTPS, but it only supports HTTP.
You're accessing the development server over HTTPS, but it only supports HTTP.
You're accessing the development server over HTTPS, but it only supports HTTP.
You're accessing the development server over HTTPS, but it only supports HTTP.
